Workbook

Sheet LISTADO DE PRODUCTOS
B2: LISTADO DE PRODUCTOS PARA CATALOGO
B4: ORDEN | C4: CÓDIGO | D4: DESCRIPCIÓN
B5: 1 | C5: 5000 | D5: =VLOOKUP(C5,'LISTA DE ARTICULO'!A:C,2,0) -> Lavandina 5L-Palacio
B6: 2 | C6: 5002 | D6: =VLOOKUP(C6,'LISTA DE ARTICULO'!A:C,2,0) -> Desodorante 5L-lavanda+
B7: 3 | C7: 5001 | D7: =VLOOKUP(C7,'LISTA DE ARTICULO'!A:C,2,0) -> Detergente Super 5L.
B8: 4 | C8: 5459 | D8: =VLOOKUP(C8,'LISTA DE ARTICULO'!A:C,2,0) -> Jabón Líq.Ropa 5L-Palacio
B9: 5 | C9: 1044 | D9: =VLOOKUP(C9,'LISTA DE ARTICULO'!A:C,2,0) -> Suavizante Palacio 5L.
B10: 6 | C10: 1218 | D10: =VLOOKUP(C10,'LISTA DE ARTICULO'!A:C,2,0) -> Hipoclorito 100% 5L-Palacio
B11: 7 | C11: 10109 | D11: =VLOOKUP(C11,'LISTA DE ARTICULO'!A:C,2,0) -> Zelnova Desinf.5L-viricida
B12: 8 | C12: 2907 | D12: =VLOOKUP(C12,'LISTA DE ARTICULO'!A:C,2,0) -> Zelnova Remocer 5L.limp.desengrasante total
B13: 9 | C13: 2910 | D13: =VLOOKUP(C13,'LISTA DE ARTICULO'!A:C,2,0) -> Zelnova Autob.5L.incoloro
B14: 10 | C14: 2913 | D14: =VLOOKUP(C14,'LISTA DE ARTICULO'!A:C,2,0) -> Remocer/Zelnova Acond.piso 5L.(t/Echo)
B15: 11 | C15: 3510 | D15: =VLOOKUP(C15,'LISTA DE ARTICULO'!A:C,2,0) -> Zelnova Quitasarro 5L.
B16: 12 | C16: 2916 | D16: =VLOOKUP(C16,'LISTA DE ARTICULO'!A:C,2,0) -> Zelnova Vidrios 5L.
... B75: 71 | C75: 4257 | D75: =VLOOKUP(C75,'LISTA DE ARTICULO'!A:C,2,0) -> Cabo Ext.Alum.2x2-make(azul)liviano
B76: 72 | C76: 2694 | D76: =VLOOKUP(C76,'LISTA DE ARTICULO'!A:C,2,0) -> Cabo Ext.Alum.3x1.50m.(negro)prof-R | F76: =72/6 -> 12
B77: 73 | C77: 2634 | D77: =VLOOKUP(C77,'LISTA DE ARTICULO'!A:C,2,0) -> Andén Barrendero 100-Cariño(madera)
B78: 74 | C78: 832 | D78: =VLOOKUP(C78,'LISTA DE ARTICULO'!A:C,2,0) -> Anden Cerda 80cm
B79: 75 | C79: 1810 | D79: =VLOOKUP(C79,'LISTA DE ARTICULO'!A:C,2,0) -> Secador Alum.100cm-piso
B80: 76 | C80: 100204 | D80: =VLOOKUP(C80,'LISTA DE ARTICULO'!A:C,2,0) -> Fiorentina Secador Aqua 40cm.Plus-3M
B81: 77 | C81: 71 | D81: =VLOOKUP(C81,'LISTA DE ARTICULO'!A:C,2,0) -> Cabo Madera 1.30 C/rosca-Pino
B82: 78 | C82: 1934 | D82: =VLOOKUP(C82,'LISTA DE ARTICULO'!A:C,2,0) -> Cabo Madera 1.50m.c/rosca
B83: 79 | C83: 3910 | D83: =VLOOKUP(C83,'LISTA DE ARTICULO'!A:C,2,0) -> Vileda Easy Wring Balde
B84: 80 | C84: 849 | D84: =VLOOKUP(C84,'LISTA DE ARTICULO'!A:C,2,0) -> Iberia Pronto Turbo Matic Balde Mop
B85: 81 | C85: 4195 | D85: =VLOOKUP(C85,'LISTA DE ARTICULO'!A:C,2,0) -> Señal Piso Mojado Busgran/Rubber
B86: 82 | C86: 5116 | D86: =VLOOKUP(C86,'LISTA DE ARTICULO'!A:C,2,0) -> Cono Señalador Caution Amarillo-M
B87: 83 | C87: 1226 | D87: =VLOOKUP(C87,'LISTA DE ARTICULO'!A:C,2,0) -> Balde Mop-Extralimp(centrifugo acero)2mopas
B88: 84 | C88: 122 | D88: =VLOOKUP(C88,'LISTA DE ARTICULO'!A:C,2,0) -> Iberia Windomatic(limpiavidrios)Todo en uno
... B106: 102 | C106: 4177 | D106: =VLOOKUP(C106,'LISTA DE ARTICULO'!A:C,2,0) -> Felp.Barrera Sanitaria 60x90cm-gris

Sheet LISTA DE ARTICULO
A2: CATÁLOGO DE ARTÍCULOS
A4: CÓDIGO | B4: DESCRIPCIÓN
A5: 1 | B5: Ayudin Lav.Gel 1500ml-Original
A6: 1 | B6: VARIOS
A7: 10 | B7: BIOFAX Cera Madera 1L.
A8: 100 | B8: P.H.8x300m.cono chico-Palacio/High
A9: 1000 | B9: Campanita Serv.x70-blanca ultra
A10: 10000 | B10: Quitaesmalte 100-humectante P.Allen/Algabo
A11: 100001 | B11: Estropajo 20g.Schez/bonux
A12: 1000013 | B12: Sedal Acond.300 d/p.Crema Balance
A13: 100005 | B13: MosquiTrap Tabletas x24-disc.
A14: 100006 | B14: Alto Poder Tabl.x24-mosquitos-disc.
A15: 100007 | B15: Finish Deterg.1kg.botella-PROMO
A16: 100008 | B16: MITT Esponja-mitón especial
... A3000: 3213 | B3000: Dove Ac.200ml-regenerac.extrema
A3001: 3213| | B3001: Rep.Navideño 40x60-Capullo*
A3002: 3214 | B3002: SUMMI.Guante Chico-disc.
A3003: 3215 | B3003: Dove Sh.200ml-Oleo nutrición
A3004: 3216 | B3004: Mr.Frend Aero 360-Multilustrador*
A3005: 3217 | B3005: Clean-tex T.Piso Gris Costurado 48x60cm-disc.
A3006: 3218 | B3006: Barral Alum.Gris 2m.(minilujo)-Eliplast054-disc.
A3007: 3219 | B3007: Leño Jabón Ocre 200g.suelto
A3008: 322 | B3008: Rexona Roll 50ml-active emotion*
A3009: 3220 | B3009: Romyl Esponja Fibra Fácil (spunita)
A3010: 3221 | B3010: Clean-tex Rejilla nido abeja-disc.
A3011: 3222 | B3011: Candado Bronce 50mm c/llave
A3012: 3223 | B3012: Agua Destilada 5L.
A3013: 3224 | B3013: Lavador 45c/abras.Rep-Royco
... A4873: 5002 | B4873: Desodorante 5L-lavanda+
A4874: 5002-1 | B4874: Desodorante 5L-floral-disc.
A4875: 5002-2 | B4875: Desodorante 5L-limón
A4876: 5002-3 | B4876: Desodorante 5L-cherry+
A4877: 5002-4 | B4877: Desodorante 5L-pino
A4878: 5002-5 | B4878: Desodorante 5L-marina-disc.
A4879: 5002-6 | B4879: Desodorante Piso 5L-citronella Palacio
A4880: 5002-8 | B4880: Desodorante 5L-Arpege+
A4881: 5003 | B4881: DESODORANTE AEROSOL
A4882: 5004 | B4882: Rexona Alcohol Gel 5L.-disc.
A4883: 5005 | B4883: Trapo Cons.Blanco 60x70-disc.
A4884: 5006 | B4884: Franela Cinco-Tes 40x50-extra-disc.
...
